Workbook

Sheet Dashboard
A1: FINANCIAL DASHBOARD
A2: Academic Year 2026-2027
A4: KEY METRICS
A5: Total Budget | C5: YTD Income | E5: YTD Expenses
A6: ='Annual Budget'!C32 | C6: ='Monthly Tracker'!C15 | E6: ='Monthly Tracker'!E15
A8: BUDGET HEALTH
A9: Current Status: | C9: =IF('Annual Budget'!C34>=0,"BALANCED ✓","DEFICIT ⚠")
A10: Available Funds: | C10: ='Monthly Tracker'!C23
A11: Budget Utilization: | C11: =IF('Annual Budget'!C32<>0,'Monthly Tracker'!E15/'Annual Budget'!C32,0)
A13: QUICK STATS
A14: Net Position: | B14: ='Annual Budget'!C34
A15: Remaining Budget: | B15: ='Annual Budget'!C32-'Monthly Tracker'!E15
A16: Months Remaining: | B16: Manual Entry
A18: NOTES & REMINDERS
A19: • Update Monthly Tracker regularly with actual income and expenses
A20: • Review Dashboard weekly to monitor budget health
A21: • Green status = on track, Yellow = caution, Red = over budget
A22: • Keep all receipts and documentation for audit purposes
A23: • Communicate with exec board about any significant variances

Sheet Instructions
A1: STUDENT ORGANIZATION BUDGET TEMPLATE
A2: Your Complete Guide to Financial Planning & Management
A4: WELCOME!
A5: This workbook is designed to help student organization treasurers plan, track, and report on their organization's finances. Whether you're managing a $2,000 budget or $50,000+, this template will help you stay organized and make informed financial decisions.
A8: HOW TO USE THIS WORKBOOK
A9: 1. Start with Annual Budget Planner | B9: Fill in your expected income sources and planned expenses for the year. All formulas will auto-calculate.
A10: 2. Break Down by Semester | B10: Use the Semester Breakdown sheet to allocate your budget between Fall and Spring.
A11: 3. Plan Individual Events | B11: Use the Event Budget Calculator for each major event. Track costs and revenue per event.
A12: 4. Track Monthly Progress | B12: Throughout the year, use Monthly Tracker to compare budgeted vs actual spending.
A13: 5. Request Funding | B13: Use the Allocation Request sheet to professionally present your budget to student government.
A14: 6. Year-End Reporting | B14: At year end, use the Year-End Report to summarize your financial performance.
A15: 7. Monitor Dashboard | B15: Check the Dashboard regularly for visual summaries of your financial health.
A16: 8. Review Example Sheet | B16: See the Example sheet for a completed budget to guide you.
A18: KEY DEFINITIONS
A19: Income | B19: Money coming into your organization (allocations, fundraising, dues, etc.)
A20: Expenses | B20: Money going out of your organization (event costs, supplies, etc.)
A21: Fixed Costs | B21: Expenses that stay the same (membership fees, subscriptions, etc.)
A22: Variable Costs | B22: Expenses that change based on activity (event food, printing, etc.)
A23: Surplus | B23: When income exceeds expenses (you have money left over)
A24: Deficit | B24: When expenses exceed income (you're spending more than you have)
A25: Contingency Fund | B25: 10% of budget set aside for unexpected expenses
A26: Variance | B26: Difference between budgeted and actual amounts
A27: Allocation | B27: Funding provided by student government
A28: Rollover | B28: Funds carried over from previous year
A30: BUDGETING BEST PRACTICES
A31: 1. | B31: Be realistic with income projections - it's better to underestimate than overestimate
A32: 2. | B32: Always include a contingency fund (10% of total budget minimum)
A33: 3. | B33: Track actual spending monthly - don't wait until year end
A34: 4. | B34: Keep receipts and documentation for all expenses
A35: 5. | B35: Review your budget with your advisor before submitting allocation requests
A36: 6. | B36: Plan for seasonal variations (Fall vs Spring spending)
A37: 7. | B37: Build in buffer time and money for events (things always cost more than expected)
A38: 8. | B38: Communicate with your exec board regularly about financial status
A39: 9. | B39: Start budget planning 2-3 months before allocation deadlines
A40: 10. | B40: Learn from previous years - review past spending patterns
A42: TIPS FOR PRESENTING TO ALLOCATION BOARDS
A43: 1. | B43: Know your numbers - be able to explain every line item
A44: 2. | B44: Show impact - connect budget requests to student outcomes
A45: 3. | B45: Be transparent about challenges and needs
A46: 4. | B46: Demonstrate responsible past financial management
...

Sheet Annual Budget
A1: ANNUAL BUDGET PLANNER
A2: Academic Year: 2026-2027
A3: Organization Name:
A5: INCOME SOURCES | C5: PROJECTED AMOUNT | D5: NOTES
A6: Student Government Allocation | D6: Funding from student government/activities board
A7: Fundraising Revenue | D7: Money raised through fundraising events, sales, etc.
A8: Membership Dues | D8: Fees collected from members
A9: Event Ticket Sales | D9: Revenue from ticketed events
A10: Sponsorships | D10: Corporate or department sponsorships
A11: Donations | D11: Individual or alumni donations
A12: Grants | D12: External grants or awards
A13: Rollover from Previous Year | D13: Funds carried over from last year
A14: Other Income | D14: Any other income sources
A15: TOTAL PROJECTED INCOME | C15: =SUM(C6:C14)
A18: EXPENSE CATEGORIES | C18: BUDGETED AMOUNT | D18: NOTES
A19: Events & Programming | D19: Costs for events, activities, programs
A20: Food & Catering | D20: Food for meetings, events, etc.
A21: Marketing & Printing | D21: Flyers, posters, social media ads
A22: Travel & Transportation | D22: Conference travel, transportation costs
A23: Supplies & Materials | D23: Office supplies, event materials
A24: Speaker/Performer Fees | D24: Payment for speakers, entertainers
A25: Equipment & Technology | D25: Tech purchases, equipment rental
A26: Venue Rental | D26: Room rentals, facility fees
A27: Merchandise & Apparel | D27: T-shirts, promotional items
A28: Administrative Costs | D28: Insurance, registration fees, bank fees
A29: Professional Development | D29: Training, workshops for members
A30: Other Expenses | D30: Any other expense categories
A31: Contingency Fund (10%) | C31: =SUM(C19:C30)*0.10 | D31: Auto-calculated: 10% of total expenses
A32: TOTAL BUDGETED EXPENSES | C32: =SUM(C19:C30)+C31
A35: BUDGET SUMMARY
A36: Total Projected Income | C36: =C15
A37: Total Budgeted Expenses | C37: =C32
A38: NET POSITION (Surplus/Deficit) | C38: =C15-C32
A39: Budget Status | C39: =IF(C38>=0,"BALANCED ✓","DEFICIT ⚠")

Sheet Semester Breakdown
A1: SEMESTER BREAKDOWN
A2: Allocate your annual budget between Fall and Spring semesters
A4: CATEGORY | B4: ANNUAL TOTAL | C4: FALL SEMESTER | D4: SPRING SEMESTER | E4: VARIANCE
A5: INCOME
A6: Student Government Allocation | E6: =B6-(C6+D6)
A7: Fundraising Revenue | E7: =B7-(C7+D7)
A8: Membership Dues | E8: =B8-(C8+D8)
A9: Event Ticket Sales | E9: =B9-(C9+D9)
A10: Sponsorships | E10: =B10-(C10+D10)
A11: Other Income | E11: =B11-(C11+D11)
A12: TOTAL INCOME | B12: =SUM(B6:B11) | C12: =SUM(C6:C11) | D12: =SUM(D6:D11) | E12: =SUM(E6:E11)
A14: EXPENSES
A15: Events & Programming | E15: =B15-(C15+D15)
A16: Food & Catering | E16: =B16-(C16+D16)
A17: Marketing & Printing | E17: =B17-(C17+D17)
A18: Travel & Transportation | E18: =B18-(C18+D18)
A19: Supplies & Materials | E19: =B19-(C19+D19)
A20: Speaker/Performer Fees | E20: =B20-(C20+D20)
A21: Equipment & Technology | E21: =B21-(C21+D21)
A22: Administrative Costs | E22: =B22-(C22+D22)
A23: Contingency Fund | E23: =B23-(C23+D23)
A24: TOTAL EXPENSES | B24: =SUM(B15:B23) | C24: =SUM(C15:C23) | D24: =SUM(D15:D23) | E24: =SUM(E15:E23)
A26: NET POSITION | C26: =C14-C24 | D26: =D14-D24
A28: NOTE: Variance column shows if Fall + Spring allocation matches Annual Total. Should be $0.

Sheet Event Calculator
A1: EVENT BUDGET CALCULATOR
A2: Use this template to budget for individual events
A4: Event Name:
A5: Event Date:
A6: Expected Attendance:
A8: EVENT INCOME | C8: AMOUNT
A9: Ticket Sales
A10: Event Sponsorships
A11: Donations
A12: Other Income
A13: TOTAL EVENT INCOME | C13: =SUM(C9:C12)
A15: EVENT EXPENSES | C15: AMOUNT
A16: Venue Rental
A17: Food & Catering
A18: Entertainment/Speaker Fees
A19: Decorations
A20: Marketing & Promotion
A21: Supplies & Materials
A22: Equipment Rental
A23: Staff/Security
A24: Contingency (10%)
A25: Other Expenses
A26: TOTAL EVENT EXPENSES | C26: =SUM(C16:C25)
A28: EVENT SUMMARY
A29: Total Income | C29: =C13
A30: Total Expenses | C30: =C26
A31: Net Profit/Loss | C31: =C13-C26
A32: Cost Per Attendee | C32: =IF(B6>0,C26/B6,0)
A33: Break-Even Ticket Price | C33: =IF(B6>0,C26/B6,0)

Sheet Monthly Tracker
A1: MONTHLY BUDGET TRACKER
A2: Track budgeted vs actual income and expenses each month
A4: MONTH | B4: BUDGETED INCOME | C4: ACTUAL INCOME | D4: BUDGETED EXPENSES | E4: ACTUAL EXPENSES | F4: NET POSITION | G4: VARIANCE
A5: August | F5: =C5-E5 | G5: =(C5-B5)+(D5-E5)
A6: September | F6: =C6-E6 | G6: =(C6-B6)+(D6-E6)
A7: October | F7: =C7-E7 | G7: =(C7-B7)+(D7-E7)
A8: November | F8: =C8-E8 | G8: =(C8-B8)+(D8-E8)
A9: December | F9: =C9-E9 | G9: =(C9-B9)+(D9-E9)
A10: January | F10: =C10-E10 | G10: =(C10-B10)+(D10-E10)
A11: February | F11: =C11-E11 | G11: =(C11-B11)+(D11-E11)
A12: March | F12: =C12-E12 | G12: =(C12-B12)+(D12-E12)
A13: April | F13: =C13-E13 | G13: =(C13-B13)+(D13-E13)
A14: May | F14: =C14-E14 | G14: =(C14-B14)+(D14-E14)
A15: YEAR-TO-DATE TOTALS | B15: =SUM(B5:B14) | C15: =SUM(C5:C14) | D15: =SUM(D5:D14) | E15: =SUM(E5:E14) | F15: =C15-E15 | G15: =SUM(G5:G14)
A18: RUNNING BALANCE
A19: Starting Balance (Rollover):
A20: YTD Income: | C20: =C15
A21: YTD Expenses: | C21: =E15
A22: CURRENT BALANCE: | C22: =C19+C20-C21

Sheet Allocation Request
A1: STUDENT GOVERNMENT ALLOCATION REQUEST
A2: Academic Year: 2026-2027
A4: ORGANIZATION INFORMATION
A5: Organization Name:
A6: Mission Statement:
A7: Number of Active Members:
A8: Primary Contact Name:
A9: Contact Email:
A10: Faculty Advisor:
A12: FUNDING REQUEST SUMMARY
A13: TOTAL AMOUNT REQUESTED:
A15: DETAILED BUDGET BREAKDOWN | C15: REQUESTED AMOUNT | D15: JUSTIFICATION
A16: Events & Programming
A17: Food & Catering
A18: Marketing & Printing
A19: Travel & Transportation
A20: Supplies & Materials
A21: Speaker/Performer Fees
A22: Equipment & Technology
A23: Administrative Costs
A24: Contingency Fund
A25: TOTAL REQUESTED | C25: =SUM(C16:C24)
A27: PREVIOUS YEAR FINANCIAL SUMMARY
A28: Previous Year Allocation:
A29: Amount Spent:
A30: Number of Events Held:
A31: Total Student Attendance:
A33: IMPACT & OUTCOMES
A34: Describe the impact this funding will have on the student body:
A39: Key metrics/outcomes you will track:

Sheet Year-End Report
A1: YEAR-END FINANCIAL REPORT
A2: Academic Year: 2026-2027
A3: Organization Name:
A5: EXECUTIVE SUMMARY
A6: METRIC | B6: BUDGETED | C6: ACTUAL | D6: VARIANCE | E6: VARIANCE %
A7: Total Income | D7: =C7-B7 | E7: =IF(B7<>0,(C7-B7)/B7,0)
A8: Total Expenses | D8: =C8-B8 | E8: =IF(B8<>0,(C8-B8)/B8,0)
A9: Net Position | D9: =C9-B9 | E9: =IF(B9<>0,(C9-B9)/B9,0)
A11: INCOME BREAKDOWN
A12: SOURCE | B12: BUDGETED | C12: ACTUAL | D12: VARIANCE | E12: VARIANCE %
A13: Student Government Allocation | D13: =C13-B13 | E13: =IF(B13<>0,(C13-B13)/B13,0)
A14: Fundraising Revenue | D14: =C14-B14 | E14: =IF(B14<>0,(C14-B14)/B14,0)
A15: Membership Dues | D15: =C15-B15 | E15: =IF(B15<>0,(C15-B15)/B15,0)
A16: Event Ticket Sales | D16: =C16-B16 | E16: =IF(B16<>0,(C16-B16)/B16,0)
A17: Sponsorships | D17: =C17-B17 | E17: =IF(B17<>0,(C17-B17)/B17,0)
A18: Other Income | D18: =C18-B18 | E18: =IF(B18<>0,(C18-B18)/B18,0)
A19: TOTAL INCOME | B19: =SUM(B13:B18) | C19: =SUM(C13:C18) | D19: =C19-B19 | E19: =IF(B19<>0,(C19-B19)/B19,0)
A21: EXPENSE BREAKDOWN
A22: CATEGORY | B22: BUDGETED | C22: ACTUAL | D22: VARIANCE | E22: VARIANCE %
A23: Events & Programming | D23: =C23-B23 | E23: =IF(B23<>0,(C23-B23)/B23,0)
A24: Food & Catering | D24: =C24-B24 | E24: =IF(B24<>0,(C24-B24)/B24,0)
A25: Marketing & Printing | D25: =C25-B25 | E25: =IF(B25<>0,(C25-B25)/B25,0)
A26: Travel & Transportation | D26: =C26-B26 | E26: =IF(B26<>0,(C26-B26)/B26,0)
A27: Supplies & Materials | D27: =C27-B27 | E27: =IF(B27<>0,(C27-B27)/B27,0)
A28: Speaker/Performer Fees | D28: =C28-B28 | E28: =IF(B28<>0,(C28-B28)/B28,0)
A29: Equipment & Technology | D29: =C29-B29 | E29: =IF(B29<>0,(C29-B29)/B29,0)
A30: Administrative Costs | D30: =C30-B30 | E30: =IF(B30<>0,(C30-B30)/B30,0)
A31: Contingency Fund | D31: =C31-B31 | E31: =IF(B31<>0,(C31-B31)/B31,0)
A32: TOTAL EXPENSES | B32: =SUM(B23:B31) | C32: =SUM(C23:C31) | D32: =C32-B32 | E32: =IF(B32<>0,(C32-B32)/B32,0)
A34: KEY ACHIEVEMENTS & METRICS
A35: Total Events Held:
A36: Total Student Attendance:
A37: New Members Recruited:
A38: Funds Raised (External):
A39: Community Service Hours:
A41: FUND ROLLOVER
A42: Ending Balance:
A43: Funds to Rollover to Next Year: | C43: =C42

Sheet Example
A1: EXAMPLE BUDGET - Computer Science Club
A2: Academic Year: 2026-2027
A3: Organization Name: Computer Science Club
A5: INCOME SOURCES | C5: PROJECTED AMOUNT | D5: NOTES
A6: Student Government Allocation | C6: 8000 | D6: Main funding source
A7: Fundraising Revenue | C7: 2000 | D7: Hackathon sponsorships
A8: Membership Dues | C8: 1500 | D8: 50 members x $30
A9: Event Ticket Sales | C9: 800 | D9: Tech talks and workshops
A10: Sponsorships | C10: 3000 | D10: Local tech companies
A11: Donations | C11: 500 | D11: Alumni donations
A12: Grants | C12: 0
A13: Rollover from Previous Year | C13: 1200 | D13: Ending balance from last year
A14: Other Income | C14: 0
A15: TOTAL PROJECTED INCOME | C15: =SUM(C6:C14)
A18: EXPENSE CATEGORIES | C18: BUDGETED AMOUNT | D18: NOTES
A19: Events & Programming | C19: 6000 | D19: Hackathon, tech talks, workshops
A20: Food & Catering | C20: 3500 | D20: Weekly meetings + event catering
A21: Marketing & Printing | C21: 800 | D21: Flyers, banners, social media
A22: Travel & Transportation | C22: 2000 | D22: Conference travel for officers
A23: Supplies & Materials | C23: 600 | D23: Office supplies, swag
A24: Speaker/Performer Fees | C24: 1500 | D24: Guest speakers for tech talks
A25: Equipment & Technology | C25: 1200 | D25: Raspberry Pi kits, software licenses
A26: Venue Rental | C26: 0 | D26: Using campus facilities
A27: Merchandise & Apparel | C27: 800 | D27: Club t-shirts
A28: Administrative Costs | C28: 200 | D28: Bank fees, insurance
A29: Professional Development | C29: 400 | D29: Officer training
A30: Other Expenses | C30: 300 | D30: Miscellaneous
A31: Contingency Fund (10%) | C31: =SUM(C19:C30)*0.10 | D31: Auto-calculated: 10% of total expenses
A32: TOTAL BUDGETED EXPENSES | C32: =SUM(C19:C30)+C31
A35: BUDGET SUMMARY
A36: Total Projected Income | C36: =C15
A37: Total Budgeted Expenses | C37: =C32
A38: NET POSITION (Surplus/Deficit) | C38: =C15-C32
A39: Budget Status | C39: BALANCED ✓
